2022-11-14 20:00:26,633 - instabot version: 0.117.0 (bot) - INFO - Instabot version: 0.117.0 Started
2022-11-14 20:00:26,634 - instabot version: 0.117.0 (bot) - DEBUG - Bot imported from C:\Users\birdl\AppData\Local\Programs\Python\Python310\lib\site-packages\instabot\bot\bot.py
2022-11-14 20:00:26,635 - instabot version: 0.117.0 (api_login) - INFO - Not yet logged in starting: PRE-LOGIN FLOW!
2022-11-14 20:00:26,715 - instabot version: 0.117.0 (api) - WARNING - HTTPSConnectionPool(host='i.instagram.com', port=443): Max retries exceeded with url: /api/v1/accounts/get_prefill_candidates/ (Caused by NewConnectionError('<urllib3.connection.HTTPSConnection object at 0x00000219A71215A0>: Failed to establish a new connection: [Errno 11001] getaddrinfo failed'))
2022-11-14 20:00:26,733 - instabot version: 0.117.0 (api) - WARNING - HTTPSConnectionPool(host='i.instagram.com', port=443): Max retries exceeded with url: /api/v1/qe/sync/ (Caused by NewConnectionError('<urllib3.connection.HTTPSConnection object at 0x00000219A7121510>: Failed to establish a new connection: [Errno 11001] getaddrinfo failed'))
2022-11-14 20:00:26,747 - instabot version: 0.117.0 (api) - WARNING - HTTPSConnectionPool(host='i.instagram.com', port=443): Max retries exceeded with url: /api/v1/launcher/sync/ (Caused by NewConnectionError('<urllib3.connection.HTTPSConnection object at 0x00000219A7121450>: Failed to establish a new connection: [Errno 11001] getaddrinfo failed'))
2022-11-14 20:00:26,762 - instabot version: 0.117.0 (api) - WARNING - HTTPSConnectionPool(host='i.instagram.com', port=443): Max retries exceeded with url: /api/v1/accounts/contact_point_prefill/ (Caused by NewConnectionError('<urllib3.connection.HTTPSConnection object at 0x00000219A7121480>: Failed to establish a new connection: [Errno 11001] getaddrinfo failed'))
